<?xml version="1.0" ?>
<robot name="robotRTB">

<!-- KINEMATICS (joints) -->
  <joint name="world_joint" type="fixed">
    <parent link="world"/>
    <child link="base_link"/>
    <origin rpy="0.0 0.0 0.0" xyz="0.0 0.0 0.0"/>
  </joint>
  <joint name="joint1" type="continuous">
    <parent link="base_link"/>
    <child link="link1"/>
    <origin rpy="0.0 -0.0 0.0" xyz="0.0 0.0 0.333"/>
    <axis xyz="0 0 1"/>
  </joint>
  <joint name="joint2" type="continuous">
    <parent link="link1"/>
    <child link="link2"/>
    <origin rpy="-1.5707963267948966 -0.0 0.0" xyz="0.0 0.0 0.0"/>
    <axis xyz="0 0 1"/>
  </joint>
  <joint name="joint3" type="continuous">
    <parent link="link2"/>
    <child link="link3"/>
    <origin rpy="1.5707963267948966 -0.0 0.0" xyz="0.0 -0.316 1.934941942652818e-17"/>
    <axis xyz="0 0 1"/>
  </joint>
  <joint name="joint4" type="continuous">
    <parent link="link3"/>
    <child link="link4"/>
    <origin rpy="1.5707963267948966 -0.0 0.0" xyz="0.0825 0.0 0.0"/>
    <axis xyz="0 0 1"/>
  </joint>
  <joint name="joint5" type="continuous">
    <parent link="link4"/>
    <child link="link5"/>
    <origin rpy="-1.5707963267948966 -0.0 0.0" xyz="-0.0825 0.384 2.3513218543629182e-17"/>
    <axis xyz="0 0 1"/>
  </joint>
  <joint name="joint6" type="continuous">
    <parent link="link5"/>
    <child link="link6"/>
    <origin rpy="1.5707963267948966 -0.0 0.0" xyz="0.0 0.0 0.0"/>
    <axis xyz="0 0 1"/>
  </joint>
  <joint name="joint7" type="continuous">
    <parent link="link6"/>
    <child link="link7"/>
    <origin rpy="1.5707963267948966 -0.0 0.0" xyz="0.088 -0.107 6.55186037543834e-18"/>
    <axis xyz="0 0 1"/>
  </joint>
  <joint name="ee_joint" type="fixed">
    <parent link="link7"/>
    <child link="ee_link"/>
    <origin rpy="0.0 -0.0 -0.7853981633974483" xyz="0.0 0.0 0.10300000000000001"/>
  </joint>

<!-- DYNAMICS (links) -->
  <link name="world"/>
  <link name="base_link"/>
  <link name="link1"/>
  <link name="link2"/>
  <link name="link3"/>
  <link name="link4"/>
  <link name="link5"/>
  <link name="link6"/>
  <link name="link7"/>
  <link name="ee_link"/>

</robot>
